Workbook

Sheet Start Here
A1: BBOS Pricing & Margin Calculator — Version 1
A3: Purpose
A4: Turn a Cost Stack and Target Margin into a defensible price using the BBOS method:
A5: Price = Cost Stack ÷ (1 − Target Margin)
A6: Margin = (Price − Cost Stack) ÷ Price
A8: How to use
A9: 1. Go to the Inputs sheet. Set your currency symbol first.
A10: 2. Enter Core (and optionally Entry / Premium) Cost Stack layers.
A11: 3. Enter Target Margin % and Margin Guardrail % (your choices — not universal).
A12: 4. Enter Optional item Cost Stacks if needed.
A13: 5. Read Results. Exact formula outputs appear first.
A14: 6. Optionally enter a practical quoted price (upward rounding only).
... A33: For planning only. Not tax, accounting, financial, or legal advice.

Sheet Inputs
A1: INPUTS — edit gold-bordered cells only
A2: Illustrative defaults follow Maya (USD). Replace with your local inputs.
A4: Currency symbol | B4: $ | C4: Currency-neutral: change this symbol for your locale.
A6: Target Margin | B6: 0.3 | C6: Planned margin for normal pricing. Your choice — not a universal recommendation.
A7: Margin Guardrail | B7: 0.2 | C7: Lowest planned margin without Exception Approval.
A9: Scenario A margin | B9: 0.25
A10: Scenario B margin | B10: 0.3
A11: Scenario C margin | B11: 0.35
A13: CORE COST STACK
A14: Layer | B14: Amount | C14: Notes
A15: Direct costs | B15: 20 | C15: Supplies + standard property linen processing
A16: Labor hours | B16: 3 | C16: Hours to deliver (include your time)
A17: Labor cost per hour | B17: 20 | C17: What the hour is worth to the business
A18: Overhead allocation | B18: 15 | C18: Simple per-job share
A19: Contingency | B19: 10 | C19: Inside Cost Stack — not the same as Target Margin
A20: Labor subtotal (calculated) | B20: =B16*B17
A21: CORE Cost Stack (calculated) | B21: =B15+B20+B18+B19
A23: ENTRY COST STACK
A24: Direct costs | B24: 12
A25: Labor hours | B25: 2
A26: Labor cost per hour | B26: 20
A27: Overhead allocation | B27: 10
A28: Contingency | B28: 8
A29: Labor subtotal | B29: =B25*B26
A30: ENTRY Cost Stack | B30: =B24+B29+B27+B28
A32: PREMIUM COST STACK
A33: Direct costs | B33: 28
A34: Labor hours | B34: 6
A35: Labor cost per hour | B35: 20
A36: Overhead allocation | B36: 20
A37: Contingency | B37: 7
A38: Labor subtotal | B38: =B34*B35
A39: PREMIUM Cost Stack | B39: =B33+B38+B36+B37
A41: OPTIONAL ITEMS (each priced separately)
A42: Optional item name | B42: Cost Stack | C42: Notes
A43: Inside-oven / fridge deep clean | B43: 21 | C43: Labor-heavy add-on
A44: Additional guest/owner laundry | B44: 14 | C44: Outside normal turnover linen processing
A45: Consumables restock | B45: 7
C46: Add more rows as needed
A49: PRACTICAL QUOTED PRICE (optional upward round)
...

Sheet Results
A1: RESULTS — calculated (do not edit)
A2: All exact prices use: Cost ÷ (1 − margin). Status never relies on color alone.
A4: CORE
A5: Currency | B5: =Inputs!B4
A6: Core Cost Stack | B6: =Inputs!B21
A7: Target Margin | B7: =Inputs!B6
A8: Margin Guardrail | B8: =Inputs!B7
A9: Exact Core price (Target) | B9: =IF(Inputs!B6>=1,"—",Inputs!B21/(1-Inputs!B6))
A10: Verified margin at exact price | B10: =IF(OR(B9="—",NOT(ISNUMBER(B9))),"—",(B9-B6)/B9)
A11: Exact Guardrail floor | B11: =IF(Inputs!B7>=1,"—",Inputs!B21/(1-Inputs!B7))
A12: Practical Core quote (from Inputs) | B12: =IF(Inputs!B50="",B9,Inputs!B50)
A13: Verified margin at practical quote | B13: =IF(OR(B12="",B12="—",NOT(ISNUMBER(B12))),"—",(B12-B6)/B12)
A14: Status | B14: =IF(OR(NOT(ISNUMBER(B6)),NOT(ISNUMBER(B7)),B7>=1,B8>=1),"Check inputs",IF(AND(ISNUMBER(Inputs!B50),Inputs!B50<B11,Inputs!B51<>"Yes"),"Below guardrail",IF(ABS(IF(ISNUMBER(B13),B13,B10)-B7)<=0.005,"At target",IF(IF(ISNUMBER(B13),B13,B10)<B8,"Below guardrail",IF(IF(ISNUMBER(B13),B13,B10)<B7,"Between guardrail and target","At or above target")))))
A15: Rounding rule: exact results first. You may round a quote UP. Never round down through the Guardrail.
A17: SCENARIO COMPARISON (Core Cost Stack)
A18: Scenario | B18: Margin | C18: Exact price | D18: Notes
A19: A | B19: =Inputs!B9 | C19: =IF(B19>=1,"—",Inputs!B21/(1-B19)) | D19: Tighter than target (example)
A20: B | B20: =Inputs!B10 | C20: =IF(B20>=1,"—",Inputs!B21/(1-B20)) | D20: Usually matches Target Margin
A21: C | B21: =Inputs!B11 | C21: =IF(B21>=1,"—",Inputs!B21/(1-B21)) | D21: Maya example: exact $161.54; intentional quote $162
A23: OFFER LADDER PRICES (at Target Margin)
A24: Rung | B24: Cost Stack | C24: Exact price | D24: Verified margin
A25: Entry | B25: =Inputs!B30 | C25: =IF(Inputs!B6>=1,"—",B25/(1-Inputs!B6)) | D25: =IF(C25="—","—",(C25-B25)/C25)
A26: Core | B26: =Inputs!B21 | C26: =B9 | D26: =B10
A27: Premium | B27: =Inputs!B39 | C27: =IF(Inputs!B6>=1,"—",B27/(1-Inputs!B6)) | D27: =IF(C27="—","—",(C27-B27)/C27)
A29: OPTIONAL ITEM PRICES (at Target Margin)
A30: Optional item | B30: Cost Stack | C30: Exact price | D30: Verified margin
A31: =Inputs!A43 | B31: =IF(Inputs!B43="","" ,Inputs!B43) | C31: =IF(OR(B31="",Inputs!B6>=1),"",B31/(1-Inputs!B6)) | D31: =IF(OR(C31="",C31=0),"",(C31-B31)/C31)
A32: =Inputs!A44 | B32: =IF(Inputs!B44="","" ,Inputs!B44) | C32: =IF(OR(B32="",Inputs!B6>=1),"",B32/(1-Inputs!B6)) | D32: =IF(OR(C32="",C32=0),"",(C32-B32)/C32)
A33: =Inputs!A45 | B33: =IF(Inputs!B45="","" ,Inputs!B45) | C33: =IF(OR(B33="",Inputs!B6>=1),"",B33/(1-Inputs!B6)) | D33: =IF(OR(C33="",C33=0),"",(C33-B33)/C33)
A34: =Inputs!A46 | B34: =IF(Inputs!B46="","" ,Inputs!B46) | C34: =IF(OR(B34="",Inputs!B6>=1),"",B34/(1-Inputs!B6)) | D34: =IF(OR(C34="",C34=0),"",(C34-B34)/C34)
A35: =Inputs!A47 | B35: =IF(Inputs!B47="","" ,Inputs!B47) | C35: =IF(OR(B35="",Inputs!B6>=1),"",B35/(1-Inputs!B6)) | D35: =IF(OR(C35="",C35=0),"",(C35-B35)/C35)
A37: Optional items never auto-include into Core. Price each separately. Not Included work stays out of the Cost Stack.

Sheet Example
A1: EXAMPLE — Maya's Property Services (illustrative USD)
A2: Illustrative example in USD. Replace the currency symbol and figures with your own local inputs. Figures are fictional — not recommended rates. Matches Module 3 Main Guide exactly.
A4: CORE COST STACK
A5: Direct costs | $20 | Supplies + standard property linen processing
A6: Labor | 3 hours × $20/hour = $60 | Owner time counts
A7: Overhead allocation | $15 | Simple per-job share
A8: Contingency | $10 | Inside Cost Stack
A9: CORE Cost Stack | $105
A11: MARGINS
A12: Target Margin | 30%
A13: Margin Guardrail | 20%
A15: CORE PRICE
... A38: Bounded exception $140 for first 4 Core turnovers (margin 25%) with end date, then return to $150

Sheet Notes and Disclaimer
A1: NOTES / DISCLAIMER
A3: For planning only. Not tax, accounting, financial, investment, or legal advice.
A4: BBOS does not guarantee profit, revenue, or any specific business result.
A6: Margin is not markup.
A7: Margin = (Price − Cost) ÷ Price
A8: Markup = (Price − Cost) ÷ Cost
A9: This calculator uses margin only.
A11: Contingency protects the job from unexpected costs.
A12: Target Margin rewards the business after all planned costs have been covered.
A14: No client data, real Bornfidis pricing, VelocityMaid data, or private credentials belong in this file.
A15: Maya's Property Services figures are fictional and illustrative.
A17: Competitor prices are not your Cost Stack. Use this calculator first;
... A21: The Main Guide defines this spreadsheet. The spreadsheet must not invent pricing behavior.
